Workbook
Name Slicer_category: #N/A
Name Slicer_primary_market: #N/A
Name Slicer_traffic_tier: #N/A

Sheet  web traffic_2026 
A1: global_rank | B1: domain | C1: category | D1: primary_market | E1: monthly_visits | F1: bounce_rate_pct | G1: avg_session_duration_min | H1: avg_session_duration_sec | I1: stickiness_index | J1: last_crawled | K1: enagement_score | L1: traffic_tier
A2: 1 | B2: google.com | C2: Social | D2: DE | E2: 996572612 | F2: 56.85 | G2: 8.3 | H2: 497.97 | I2: 14.6 | J2: 46060 | K2: =ROUND((100-F2)*0.5 + I2*0.5,2) -> 28.88 | L2: {=_xlfn.IFS(E2>=52000000,"Platinum",E2>=37000000,"Gold",E2>=30000000,"Sliver",E2<30000000,"Bronze")} -> Platinum
A3: 2 | B3: gtld-servers.net | C3: Social | D3: IN | E3: 635529412 | F3: 40.19 | G3: 4.69 | H3: 281.25 | I3: 11.66 | J3: 46060 | K3: =ROUND((100-F3)*0.5 + I3*0.5,2) -> 35.74 | L3: {=_xlfn.IFS(E3>=52000000,"Platinum",E3>=37000000,"Gold",E3>=30000000,"Sliver",E3<30000000,"Bronze")} -> Platinum
A4: 3 | B4: microsoft.com | C4: Social | D4: IN | E4: 525892610 | F4: 59.96 | G4: 8.45 | H4: 507.02 | I4: 14.09 | J4: 46060 | K4: =ROUND((100-F4)*0.5 + I4*0.5,2) -> 27.07 | L4: {=_xlfn.IFS(E4>=52000000,"Platinum",E4>=37000000,"Gold",E4>=30000000,"Sliver",E4<30000000,"Bronze")} -> Platinum
A5: 4 | B5: facebook.com | C5: News | D5: BR | E5: 589445551 | F5: 34.35 | G5: 3.23 | H5: 193.58 | I5: 9.39 | J5: 46060 | K5: =ROUND((100-F5)*0.5 + I5*0.5,2) -> 37.52 | L5: {=_xlfn.IFS(E5>=52000000,"Platinum",E5>=37000000,"Gold",E5>=30000000,"Sliver",E5<30000000,"Bronze")} -> Platinum
A6: 5 | B6: mail.ru | C6: Finance | D6: BR | E6: 402317681 | F6: 42.3 | G6: 5.02 | H6: 300.91 | I6: 11.86 | J6: 46060 | K6: =ROUND((100-F6)*0.5 + I6*0.5,2) -> 34.78 | L6: {=_xlfn.IFS(E6>=52000000,"Platinum",E6>=37000000,"Gold",E6>=30000000,"Sliver",E6<30000000,"Bronze")} -> Platinum
A7: 6 | B7: cloudflare.com | C7: Search | D7: GB | E7: 334143655 | F7: 49.34 | G7: 1.25 | H7: 74.71 | I7: 2.52 | J7: 46060 | K7: =ROUND((100-F7)*0.5 + I7*0.5,2) -> 26.59 | L7: {=_xlfn.IFS(E7>=52000000,"Platinum",E7>=37000000,"Gold",E7>=30000000,"Sliver",E7<30000000,"Bronze")} -> Platinum
A8: 7 | B8: googleapis.com | C8: Social | D8: GB | E8: 376941229 | F8: 55.65 | G8: 6.49 | H8: 389.54 | I8: 11.67 | J8: 46060 | K8: =ROUND((100-F8)*0.5 + I8*0.5,2) -> 28.01 | L8: {=_xlfn.IFS(E8>=52000000,"Platinum",E8>=37000000,"Gold",E8>=30000000,"Sliver",E8<30000000,"Bronze")} -> Platinum
A9: 8 | B9: apple.com | C9: Social | D9: JP | E9: 415012900 | F9: 39.04 | G9: 5.06 | H9: 303.73 | I9: 12.97 | J9: 46060 | K9: =ROUND((100-F9)*0.5 + I9*0.5,2) -> 36.97 | L9: {=_xlfn.IFS(E9>=52000000,"Platinum",E9>=37000000,"Gold",E9>=30000000,"Sliver",E9<30000000,"Bronze")} -> Platinum
A10: 9 | B10: youtube.com | C10: Streaming | D10: BR | E10: 296821826 | F10: 29.58 | G10: 28.58 | H10: 1715.01 | I10: 96.63 | J10: 46060 | K10: =ROUND((100-F10)*0.5 + I10*0.5,2) -> 83.53 | L10: {=_xlfn.IFS(E10>=52000000,"Platinum",E10>=37000000,"Gold",E10>=30000000,"Sliver",E10<30000000,"Bronze")} -> Platinum
A11: 10 | B11: amazonaws.com | C11: Tech | D11: DE | E11: 263102204 | F11: 38.34 | G11: 2.63 | H11: 157.76 | I11: 6.86 | J11: 46060 | K11: =ROUND((100-F11)*0.5 + I11*0.5,2) -> 34.26 | L11: {=_xlfn.IFS(E11>=52000000,"Platinum",E11>=37000000,"Gold",E11>=30000000,"Sliver",E11<30000000,"Bronze")} -> Platinum
A12: 11 | B12: instagram.com | C12: Finance | D12: DE | E12: 252270262 | F12: 52.58 | G12: 7.73 | H12: 464 | I12: 14.71 | J12: 46060 | K12: =ROUND((100-F12)*0.5 + I12*0.5,2) -> 31.07 | L12: {=_xlfn.IFS(E12>=52000000,"Platinum",E12>=37000000,"Gold",E12>=30000000,"Sliver",E12<30000000,"Bronze")} -> Platinum
A13: 12 | B13: dzen.ru | C13: News | D13: US | E13: 346164172 | F13: 55.04 | G13: 8.06 | H13: 483.48 | I13: 14.64 | J13: 46060 | K13: =ROUND((100-F13)*0.5 + I13*0.5,2) -> 29.8 | L13: {=_xlfn.IFS(E13>=52000000,"Platinum",E13>=37000000,"Gold",E13>=30000000,"Sliver",E13<30000000,"Bronze")} -> Platinum
... A15: 14 | B15: akamai.net | C15: Social | D15: US | E15: 307122589 | F15: 47.51 | G15: 5.68 | H15: 341.08 | I15: 11.97 | J15: 46060 | K15: =ROUND((100-F15)*0.5 + I15*0.5,2) -> 32.23 | L15: {=_xlfn.IFS(E15>=52000000,"Platinum",E15>=37000000,"Gold",E15>=30000000,"Sliver",E15<30000000,"Bronze")} -> Platinum
A16: 15 | B16: office.com | C16: Search | D16: IN | E16: 216739182 | F16: 47.19 | G16: 5.72 | H16: =CALCULATION!$D$11 -> 343.315 | I16: 3.89 | J16: 46060 | K16: =ROUND((100-F16)*0.5 + I16*0.5,2) -> 28.35 | L16: {=_xlfn.IFS(E16>=52000000,"Platinum",E16>=37000000,"Gold",E16>=30000000,"Sliver",E16<30000000,"Bronze")} -> Platinum
A17: 16 | B17: twitter.com | C17: Streaming | D17: BR | E17: 211271952 | F17: 19.51 | G17: 30.77 | H17: 1845.97 | I17: 157.69 | J17: 46060 | K17: =ROUND((100-F17)*0.5 + I17*0.5,2) -> 119.09 | L17: {=_xlfn.IFS(E17>=52000000,"Platinum",E17>=37000000,"Gold",E17>=30000000,"Sliver",E17<30000000,"Bronze")} -> Platinum
A18: 17 | B18: googlevideo.com | C18: Streaming | D18: JP | E18: 236317374 | F18: 22.06 | G18: 39.15 | H18: 2348.96 | I18: 177.47 | J18: 46060 | K18: =ROUND((100-F18)*0.5 + I18*0.5,2) -> 127.71 | L18: {=_xlfn.IFS(E18>=52000000,"Platinum",E18>=37000000,"Gold",E18>=30000000,"Sliver",E18<30000000,"Bronze")} -> Platinum
A19: 18 | B19: live.com | C19: Streaming | D19: IN | E19: 273843355 | F19: 28.29 | G19: 14.76 | H19: 885.83 | I19: 52.19 | J19: 46060 | K19: =ROUND((100-F19)*0.5 + I19*0.5,2) -> 61.95 | L19: {=_xlfn.IFS(E19>=52000000,"Platinum",E19>=37000000,"Gold",E19>=30000000,"Sliver",E19<30000000,"Bronze")} -> Platinum
A20: 19 | B20: linkedin.com | C20: Social | D20: US | E20: 207815027 | F20: 46.04 | G20: 3.45 | H20: 206.72 | I20: 7.48 | J20: 46060 | K20: =ROUND((100-F20)*0.5 + I20*0.5,2) -> 30.72 | L20: {=_xlfn.IFS(E20>=52000000,"Platinum",E20>=37000000,"Gold",E20>=30000000,"Sliver",E20<30000000,"Bronze")} -> Platinum
A21: 20 | B21: fbcdn.net | C21: Streaming | D21: IN | E21: 191331971 | F21: 23.77 | G21: 31.48 | H21: 1888.92 | I21: 132.44 | J21: 46060 | K21: =ROUND((100-F21)*0.5 + I21*0.5,2) -> 104.34 | L21: {=_xlfn.IFS(E21>=52000000,"Platinum",E21>=37000000,"Gold",E21>=30000000,"Sliver",E21<30000000,"Bronze")} -> Platinum
A22: 21 | B22: googletagmanager.com | C22: News | D22: DE | E22: 202396575 | F22: 42.42 | G22: 8.97 | H22: 538.05 | I22: 21.14 | J22: 46060 | K22: =ROUND((100-F22)*0.5 + I22*0.5,2) -> 39.36 | L22: {=_xlfn.IFS(E22>=52000000,"Platinum",E22>=37000000,"Gold",E22>=30000000,"Sliver",E22<30000000,"Bronze")} -> Platinum
A23: 22 | B23: akadns.net | C23: Search | D23: US | E23: 185606465 | F23: 36.09 | G23: 2.42 | H23: 145.4 | I23: 6.71 | J23: 46060 | K23: =ROUND((100-F23)*0.5 + I23*0.5,2) -> 35.31 | L23: {=_xlfn.IFS(E23>=52000000,"Platinum",E23>=37000000,"Gold",E23>=30000000,"Sliver",E23<30000000,"Bronze")} -> Platinum
A24: 23 | B24: akamaiedge.net | C24: Search | D24: IN | E24: 222002758 | F24: 44.2 | G24: 1.66 | H24: 99.63 | I24: 3.76 | J24: 46060 | K24: =ROUND((100-F24)*0.5 + I24*0.5,2) -> 29.78 | L24: {=_xlfn.IFS(E24>=52000000,"Platinum",E24>=37000000,"Gold",E24>=30000000,"Sliver",E24<30000000,"Bronze")} -> Platinum
A25: 24 | B25: amazon.com | C25: Search | D25: IN | E25: 176310109 | F25: 18.67 | G25: 14.19 | H25: 851.62 | I25: 76.02 | J25: 46060 | K25: =ROUND((100-F25)*0.5 + I25*0.5,2) -> 78.68 | L25: {=_xlfn.IFS(E25>=52000000,"Platinum",E25>=37000000,"Gold",E25>=30000000,"Sliver",E25<30000000,"Bronze")} -> Platinum
A26: 25 | B26: workers.dev | C26: E-commerce | D26: BR | E26: 200157336 | F26: 36.23 | G26: 2.19 | H26: 131.35 | I26: 6.04 | J26: 46060 | K26: =ROUND((100-F26)*0.5 + I26*0.5,2) -> 34.91 | L26: {=_xlfn.IFS(E26>=52000000,"Platinum",E26>=37000000,"Gold",E26>=30000000,"Sliver",E26<30000000,"Bronze")} -> Platinum
A27: 26 | B27: microsoftonline.com | C27: News | D27: GB | E27: 161153089 | F27: 40.06 | G27: 3.04 | H27: 182.28 | I27: 7.58 | J27: 46060 | K27: =ROUND((100-F27)*0.5 + I27*0.5,2) -> 33.76 | L27: {=_xlfn.IFS(E27>=52000000,"Platinum",E27>=37000000,"Gold",E27>=30000000,"Sliver",E27<30000000,"Bronze")} -> Platinum
A28: 27 | B28: azure.com | C28: Finance | D28: JP | E28: 167022433 | F28: 58.03 | G28: 9.37 | H28: 562.12 | I28: 16.14 | J28: 46060 | K28: =ROUND((100-F28)*0.5 + I28*0.5,2) -> 29.06 | L28: {=_xlfn.IFS(E28>=52000000,"Platinum",E28>=37000000,"Gold",E28>=30000000,"Sliver",E28<30000000,"Bronze")} -> Platinum
... A45: 44 | B45: e2ro.com | C45: Social | D45: GB | E45: 145597942 | F45: 34.43 | G45: 7.91 | H45: 474.65 | I45: 22.98 | J45: 46060 | K45: =ROUND((100-F45)*0.5 + I45*0.5,2) -> 44.28 | L45: {=_xlfn.IFS(E45>=52000000,"Platinum",E45>=37000000,"Gold",E45>=30000000,"Sliver",E45<30000000,"Bronze")} -> Platinum
A46: 45 | B46: youtu.be | C46: News | D46: IN | E46: 147816685 | F46: 39.64 | G46: 5.72 | H46: =CALCULATION!$D$11 -> 343.315 | I46: 18.31 | J46: 46060 | K46: =ROUND((100-F46)*0.5 + I46*0.5,2) -> 39.34 | L46: {=_xlfn.IFS(E46>=52000000,"Platinum",E46>=37000000,"Gold",E46>=30000000,"Sliver",E46<30000000,"Bronze")} -> Platinum
A47: 46 | B47: icloud.com | C47: Search | D47: BR | E47: 159710170 | F47: 39.79 | G47: 2.3 | H47: 138 | I47: 5.78 | J47: 46060 | K47: =ROUND((100-F47)*0.5 + I47*0.5,2) -> 33 | L47: {=_xlfn.IFS(E47>=52000000,"Platinum",E47>=37000000,"Gold",E47>=30000000,"Sliver",E47<30000000,"Bronze")} -> Platinum
A48: 47 | B48: sharepoint.com | C48: Search | D48: DE | E48: 151090731 | F48: 49.66 | G48: 2.24 | H48: 134.57 | I48: 4.52 | J48: 46060 | K48: =ROUND((100-F48)*0.5 + I48*0.5,2) -> 27.43 | L48: {=_xlfn.IFS(E48>=52000000,"Platinum",E48>=37000000,"Gold",E48>=30000000,"Sliver",E48<30000000,"Bronze")} -> Platinum
A49: 48 | B49: pinterest.com | C49: Finance | D49: DE | E49: 172362276 | F49: 57.55 | G49: 6.76 | H49: 405.68 | I49: 11.75 | J49: 46060 | K49: =ROUND((100-F49)*0.5 + I49*0.5,2) -> 27.1 | L49: {=_xlfn.IFS(E49>=52000000,"Platinum",E49>=37000000,"Gold",E49>=30000000,"Sliver",E49<30000000,"Bronze")} -> Platinum
A50: 49 | B50: trafficmanager.net | C50: E-commerce | D50: US | E50: 123203308 | F50: 46.02 | G50: 7.61 | H50: 456.76 | I50: 16.54 | J50: 46060 | K50: =ROUND((100-F50)*0.5 + I50*0.5,2) -> 35.26 | L50: {=_xlfn.IFS(E50>=52000000,"Platinum",E50>=37000000,"Gold",E50>=30000000,"Sliver",E50<30000000,"Bronze")} -> Platinum
A51: 50 | B51: ripn.net | C51: Finance | D51: BR | E51: 143340973 | F51: =CALCULATION!$C$11 -> 42.81 | G51: 4.42 | H51: 265.42 | I51: 8.71 | J51: 46060 | K51: =ROUND((100-F51)*0.5 + I51*0.5,2) -> 32.95 | L51: {=_xlfn.IFS(E51>=52000000,"Platinum",E51>=37000000,"Gold",E51>=30000000,"Sliver",E51<30000000,"Bronze")} -> Platinum
A52: 51 | B52: whatsapp.com | C52: Social | D52: JP | E52: 121938978 | F52: 49.63 | G52: 2.41 | H52: 144.54 | I52: 4.85 | J52: 46060 | K52: =ROUND((100-F52)*0.5 + I52*0.5,2) -> 27.61 | L52: {=_xlfn.IFS(E52>=52000000,"Platinum",E52>=37000000,"Gold",E52>=30000000,"Sliver",E52<30000000,"Bronze")} -> Platinum
A53: 52 | B53: yahoo.com | C53: News | D53: BR | E53: 134085268 | F53: =CALCULATION!$C$11 -> 42.81 | G53: 6.29 | H53: 377.63 | I53: 12.09 | J53: 46060 | K53: =ROUND((100-F53)*0.5 + I53*0.5,2) -> 34.64 | L53: {=_xlfn.IFS(E53>=52000000,"Platinum",E53>=37000000,"Gold",E53>=30000000,"Sliver",E53<30000000,"Bronze")} -> Platinum
A54: 53 | B54: akam.net | C54: Finance | D54: JP | E54: 158009610 | F54: 56.85 | G54: 5.72 | H54: =CALCULATION!$D$11 -> 343.315 | I54: 10.14 | J54: 46060 | K54: =ROUND((100-F54)*0.5 + I54*0.5,2) -> 26.65 | L54: {=_xlfn.IFS(E54>=52000000,"Platinum",E54>=37000000,"Gold",E54>=30000000,"Sliver",E54<30000000,"Bronze")} -> Platinum
A55: 54 | B55: windows.net | C55: E-commerce | D55: US | E55: 109356676 | F55: 47.32 | G55: 4.68 | H55: 280.79 | I55: 9.89 | J55: 46060 | K55: =ROUND((100-F55)*0.5 + I55*0.5,2) -> 31.29 | L55: {=_xlfn.IFS(E55>=52000000,"Platinum",E55>=37000000,"Gold",E55>=30000000,"Sliver",E55<30000000,"Bronze")} -> Platinum
A56: 55 | B56: googlesyndication.com | C56: Search | D56: JP | E56: 159796890 | F56: 46.18 | G56: 1.84 | H56: 110.44 | I56: 3.99 | J56: 46060 | K56: =ROUND((100-F56)*0.5 + I56*0.5,2) -> 28.91 | L56: {=_xlfn.IFS(E56>=52000000,"Platinum",E56>=37000000,"Gold",E56>=30000000,"Sliver",E56<30000000,"Bronze")} -> Platinum
A57: 56 | B57: goo.gl | C57: Finance | D57: US | E57: 149796748 | F57: 33.91 | G57: 7.2 | H57: 431.92 | I57: 21.23 | J57: 46060 | K57: =ROUND((100-F57)*0.5 + I57*0.5,2) -> 43.66 | L57: {=_xlfn.IFS(E57>=52000000,"Platinum",E57>=37000000,"Gold",E57>=30000000,"Sliver",E57<30000000,"Bronze")} -> Platinum
...

Sheet CALCULATION
C3: bounce_rate_pct | D3: avg_session_duration_s
B4: MEAN | C4: =AVERAGE(' web traffic_2026 '!F2:F1501) -> 42.02304 | D4: =AVERAGE(' web traffic_2026 '!H2:H1501) -> 471.59507
B5: MEDIAN | C5: =MEDIAN(' web traffic_2026 '!F2:F1501) -> 42.81 | D5: =MEDIAN(' web traffic_2026 '!H2:H1501) -> 343.315
B6: MODE | C6: =MODE(' web traffic_2026 '!F2:F1501) -> 42.81 | D6: =MODE(' web traffic_2026 '!H2:H1501) -> 343.315
B11: Median | C11: 42.81 | D11: 343.315
D14: tire list | G14: MODE FOR primary market | H14: {=INDEX(' web traffic_2026 '!D2:D1501,MATCH(MAX(COUNTIF(' web traffic_2026 '!D2:D1501,' web traffic_2026 '!D2:D1501)),COUNTIF(' web traffic_2026 '!D2:D1501,' web traffic_2026 '!D2:D1501),0))} -> US
C16: Q1 | D16: =_xlfn.QUARTILE.EXC(' web traffic_2026 '!E2:E1501,1) -> 30205846 | G16: Mode for category | H16: {=INDEX(' web traffic_2026 '!C2:C1501,MATCH(MAX(COUNTIF(' web traffic_2026 '!C2:C1501,' web traffic_2026 '!C2:C1501)),COUNTIF(' web traffic_2026 '!C2:C1501,' web traffic_2026 '!C2:C1501),0))} -> Search
C17: Q2 | D17: =_xlfn.QUARTILE.EXC(' web traffic_2026 '!E3:E1501,2) -> 36844437
C18: Q3 | D18: =_xlfn.QUARTILE.EXC(' web traffic_2026 '!E2:E1501,3) -> 51853510
C19: MAX | D19: =MAX(' web traffic_2026 '!E2:E1501) -> 996572612

Sheet Domain Analysis
A1: Row Labels | B1: Min of global_rank
A2: apdcdn.com | B2: 1497
A3: banvenez.com | B3: 1491
A4: cam.ac.uk | B4: 1496
A5: fastdl.app | B5: 1493
A6: fatalmodel.com | B6: 1499
A7: listcrawler.eu | B7: 1498
A8: nosv.org | B8: 1492
A9: qorno.com | B9: 1495
A10: snaptik.app | B10: 1500
A11: trustarc.com | B11: 1494
A12: Grand Total | B12: 1491
A20: Row Labels | B20: Sum of monthly_visits
A21: akamai.net | B21: 307122589 | M21: Row Labels | N21: Average of avg_session_duration_min
A22: apple.com | B22: 415012900 | M22: amazonvideo.com | N22: 38.88
A23: cloudflare.com | B23: 334143655 | M23: googlevideo.com | N23: 39.15
A24: dzen.ru | B24: 346164172 | M24: hichina.com | N24: 38.69
A25: facebook.com | B25: 589445551 | M25: ieee.org | N25: 39.76
A26: google.com | B26: 996572612 | M26: ikea.com | N26: 39.5
A27: googleapis.com | B27: 376941229 | M27: newsweek.com | N27: 39.81
A28: gtld-servers.net | B28: 635529412 | M28: nikkei.com | N28: 38.91
A29: mail.ru | B29: 402317681 | M29: primevideo.com | N29: 39.91
A30: microsoft.com | B30: 525892610 | M30: vungle.com | N30: 39.31
A31: Grand Total | B31: 4929142411 | M31: xhamster2.com | N31: 38.73
M32: Grand Total | N32: 39.265
A37: Row Labels | B37: Average of bounce_rate_pct
A38: afilias-nst.org | B38: 59.95
A39: akamaitech.net | B39: 59.88
A40: amazon.ca | B40: 59.73 | M40: Row Labels | N40: Average of enagement_score
A41: box.com | B41: 59.65 | M41: amazonvideo.com | N41: 153.44
A42: microsoft.com | B42: 59.96 | M42: google.com.hk | N42: 148.63
A43: miit.gov.cn | B43: 59.83 | M43: list-manage.com | N43: 156.83
A44: overwolf.com | B44: 59.91 | M44: motherless.com | N44: 168.75
A45: samsungqbe.com | B45: 59.72 | M45: ntppool.org | N45: 142.49
A46: skyhigh.cloud | B46: 59.63 | M46: pornhub.com | N46: 160.24
A47: ucla.edu | B47: 60 | M47: safebrowsing.apple | N47: 149.8
A48: Grand Total | B48: 59.826 | M48: unity3d.com | N48: 145.06
M49: wattpad.com | N49: 141.32
M50: xhamster2.com | N50: 169.18
M51: Grand Total | N51: 153.574
...

Sheet Category Analysis
A1: global_rank | B1: (All)
M2: Row Labels | N2: Average of bounce_rate_pct
A3: Row Labels | B3: Average of global_rank | M3: E-commerce | N3: 45.604076
A4: Streaming | B4: 709.66667 | M4: Finance | N4: 45.572319
A5: Finance | B5: 732.72947 | M5: Tech | N5: 45.286061
A6: E-commerce | B6: 740.34597 | M6: Social | N6: 45.159796
A7: Tech | B7: 750.32828 | M7: News | N7: 44.99681
A8: Search | B8: 761.62898 | M8: Search | N8: 42.056431
A9: News | B9: 773.6 | M9: Streaming | N9: 24.663436
A10: Social | B10: 780.17857 | M10: Grand Total | N10: 42.02304
A11: Grand Total | B11: 750.5 | Y11: Row Labels | Z11: Sum of monthly_visits
Y12: Search | Z12: 13940507154
Y13: Social | Z13: 11810682482
Y14: Finance | Z14: 10554953065
Y15: News | Z15: 10369181827
Y16: Streaming | Z16: 10132988790
Y17: E-commerce | Z17: 9914194608
Y18: Tech | Z18: 9038603644
A19: Row Labels | B19: Sum of monthly_visits
A20: Search | B20: 13940507154 | M20: Row Labels | N20: Average of avg_session_duration_min
A21: Social | B21: 11810682482 | M21: Streaming | N21: 24.541538
A22: Finance | B22: 10554953065 | M22: Tech | N22: 6.1105051
A23: News | B23: 10369181827 | M23: Finance | N23: 5.9381643
A24: Streaming | B24: 10132988790 | M24: E-commerce | N24: 5.9145498
A25: E-commerce | B25: 9914194608 | M25: News | N25: 5.8828095
A26: Tech | B26: 9038603644 | M26: Social | N26: 5.8677551
A27: Grand Total | B27: 75761111570 | M27: Search | N27: 3.2919788
M28: Grand Total | N28: 7.8598333
A35: Row Labels | B35: Average of stickiness_index
A36: Streaming | B36: 114.42436
A37: Tech | B37: 14.038182 | M37: Row Labels | N37: Average of enagement_score
A38: News | B38: 13.866143 | M38: Streaming | N38: 94.882974
A39: Social | B39: 13.439847 | M39: News | N39: 34.437238
A40: E-commerce | B40: 13.392844 | M40: Tech | N40: 34.378535
A41: Finance | B41: 13.380966 | M41: Social | N41: 34.142602
A42: Search | B42: 9.7118021 | M42: Finance | N42: 33.906957
A43: Grand Total | B43: 25.9884 | M43: E-commerce | N43: 33.89654
M44: Search | N44: 33.830177
M45: Grand Total | N45: 41.985167

Sheet Market Analysis
M2: Row Labels | N2: Average of bounce_rate_pct
A3: Row Labels | B3: Average of global_rank | M3: BR | N3: 41.08932
A4: BR | B4: 761.172 | M4: DE | N4: 42.697227
A5: DE | B5: 764.20168 | M5: GB | N5: 41.797783
A6: GB | B6: 732.42174 | M6: IN | N6: 41.824323 | Z6: Row Labels | AA6: Average of monthly_visits
A7: IN | B7: 734.31878 | M7: JP | N7: 41.663423 | Z7: BR | AA7: 51083493
A8: JP | B8: 773.24231 | M8: US | N8: 42.923345 | Z8: DE | AA8: 51970340
A9: US | B9: 736.9215 | M9: Grand Total | N9: 42.02304 | Z9: GB | AA9: 50869992
A10: Grand Total | B10: 750.5 | Z10: IN | AA10: 54336023
Z11: JP | AA11: 46762961
Z12: US | AA12: 48873311
A20: Row Labels | B20: Average of monthly_visits
A21: BR | B21: 51083493
A22: DE | B22: 51970340 | M22: Row Labels | N22: Average of avg_session_duration_min
A23: GB | B23: 50869992 | M23: BR | N23: 8.30136
A24: IN | B24: 54336023 | M24: DE | N24: 6.7930672
A25: JP | B25: 46762961 | M25: GB | N25: 7.8017826
A26: US | B26: 48873311 | M26: IN | N26: 8.2979913
A27: Grand Total | B27: 50507408 | M27: JP | N27: 8.0673462
M28: US | N28: 7.8686007
M29: Grand Total | N29: 7.8598333
A37: Row Labels | B37: Average of stickiness_index | M37: Row Labels | N37: Average of enagement_score
A38: BR | B38: 28.13288 | M38: BR | N38: 43.52416
A39: DE | B39: 20.961008 | M39: DE | N39: 39.134118
A40: GB | B40: 26.305522 | M40: GB | N40: 42.256261
A41: IN | B41: 27.511266 | M41: IN | N41: 42.846245
A42: JP | B42: 27.221038 | M42: JP | N42: 42.781385
A43: US | B43: 25.709352 | M43: US | N43: 41.395563
A44: Grand Total | B44: 25.9884 | M44: Grand Total | N44: 41.985167

Sheet Tier Analysis
A3: Row Labels | B3: Average of global_rank | M3: Row Labels | N3: Average of bounce_rate_pct
A4: Bronze | B4: 1233.4835 | M4: Bronze | N4: 41.963901 | Y4: Row Labels | Z4: Sum of monthly_visits
A5: Gold | B5: 582.52291 | M5: Gold | N5: 41.998464 | Y5: Bronze | Z5: 9566452096
A6: Platinum | B6: 196.93817 | M6: Platinum | N6: 41.291909 | Y6: Gold | Z6: 16028548579
A7: Sliver | B7: 985.71247 | M7: Sliver | N7: 42.793079 | Y7: Platinum | Z7: 37159155560
A8: Grand Total | B8: 750.5 | M8: Grand Total | N8: 42.02304 | Y8: Sliver | Z8: 13006955335
A20: Row Labels | B20: Sum of monthly_visits
A21: Bronze | B21: 9566452096
A22: Gold | B22: 16028548579 | M22: Row Labels | N22: Average of avg_session_duration_min
A23: Platinum | B23: 37159155560 | M23: Bronze | N23: 7.001456
A24: Sliver | B24: 13006955335 | M24: Gold | N24: 8.0352291
A25: Grand Total | B25: 75761111570 | M25: Platinum | N25: 8.5108333
M26: Sliver | N26: 7.8730789
M27: Grand Total | N27: 7.8598333
M35: Row Labels | N35: Average of enagement_score
A36: Row Labels | B36: Average of stickiness_index | M36: Bronze | N36: 40.116758
A37: Bronze | B37: 22.192308 | M37: Gold | N37: 42.497412
A38: Gold | B38: 26.988194 | M38: Platinum | N38: 43.926183
A39: Platinum | B39: 29.139624 | M39: Sliver | N39: 41.394835
A40: Sliver | B40: 25.57771 | M40: Grand Total | N40: 41.985167
A41: Grand Total | B41: 25.9884

Sheet KPI pivot
A1: Count of domain | F1: Sum of monthly_visits
A2: 1500 | F2: 75761111570
F9: Average of bounce_rate_pct
F10: 42.02304
F18: Average of enagement_score
F19: 41.985167

Sheet Dashboard
O1: GLOBAL WEBSITE TRAFFIC ANALYSIS 2026
O2: Analyzing Top 1500 Websites Across 6 Global Markets
